<?xml version="1.0" encoding="utf-8"?>
<!-- =================================================================================== -->
<!-- |    This document was autogenerated by xacro from use_case_setup_lwr.urdf.xacro  | -->
<!-- |    EDITING THIS FILE BY HAND IS NOT RECOMMENDED                                 | -->
<!-- =================================================================================== -->
<robot name="LWR" xmlns:controller="http://playerstage.sourceforge.net/gazebo/xmlschema/#controller" xmlns:interface="http://playerstage.sourceforge.net/gazebo/xmlschema/#interface" xmlns:sensor="http://playerstage.sourceforge.net/gazebo/xmlschema/#sensor">
  <material name="DarkGrey">
    <color rgba="0.3 0.3 0.3 1.0"/>
  </material>
  <material name="Black">
    <color rgba="0 0 0 1.0"/>
  </material>
  <material name="Orange">
    <color rgba="1.0 0.487 0 1.0"/>
  </material>
  <material name="Silver">
    <color rgba="1.0 1.0 1.0 1.0"/>
  </material>
  <material name="Grey">
    <color rgba="0.7 0.7 0.7 1.0"/>
  </material>
  <material name="Blue">
    <color rgba="0.0 0.0 0.8 1.0"/>
  </material>
  <material name="HandGray">
    <color rgba="0.953 0.996 0.694 1.0"/>
  </material>
  <material name="SickBlue">
    <color rgba="0.3058 0.5921 0.7294 1.0"/>
  </material>
  <material name="Wheat">
    <color rgba="0.8039 0.5215 0.2470 1.0"/>
  </material>
  <link name="world"/>
  <joint name="world_lwr_arm_base_joint" type="fixed">
    <origin rpy="0 0 0" xyz="0 0 0"/>
    <parent link="world"/>
    <child link="calib_lwr_arm_base_link"/>
  </joint>
  <link name="calib_lwr_arm_base_link">
    <inertial>
      <mass value="2.0"/>
      <origin rpy="0 0 0" xyz="0 0 0.055"/>
      <inertia ixx="0.00381666666667" ixy="0" ixz="0" iyy="0.0036" iyz="0" izz="0.00381666666667"/>
    </inertial>
    <visual>
      <origin rpy="0 0 0" xyz="0 0 0"/>
      <geometry>
        <mesh filename="package://kuka_lwr_description/meshes/arm/arm_base.stl"/>
      </geometry>
      <material name="Orange"/>
    </visual>
    <collision>
      <origin rpy="0 0 0" xyz="0 0 0"/>
      <geometry>
        <mesh filename="package://kuka_lwr_description/meshes/arm/convex/arm_base_convex.stl"/>
      </geometry>
    </collision>
  </link>
  <gazebo reference="calib_lwr_arm_base_link">
    <material value="kuka-lwr.material"/>
  </gazebo>
  <joint name="lwr_arm_joint_0" type="revolute">
    <origin rpy="0 0 0" xyz="0 0 0.11"/>
    <axis xyz="0 0 1"/>
    <limit effort="204" lower="-2.96705972839" upper="2.96705972839" velocity="1.91986217719"/>
    <safety_controller k_position="100" k_velocity="2" soft_lower_limit="-2.93215314335" soft_upper_limit="2.93215314335"/>
    <dynamics damping="0.1"/>
    <parent link="calib_lwr_arm_base_link"/>
    <child link="lwr_arm_link_1"/>
  </joint>
  <link name="lwr_arm_link_1">
    <inertial>
      <mass value="2.0"/>
      <origin rpy="0 0 0" xyz="0 0 0.130"/>
      <inertia ixx="0.0136666666667" ixy="0" ixz="0" iyy="0.003" iyz="0" izz="0.0118666666667"/>
    </inertial>
    <visual>
      <origin rpy="0 0 3.14159265359" xyz="0 0 0"/>
      <geometry>
        <mesh filename="package://kuka_lwr_description/meshes/arm/arm_segment_a.stl"/>
      </geometry>
      <material name="Orange"/>
    </visual>
    <collision>
      <origin rpy="0 0 3.14159265359" xyz="0 0 0"/>
      <geometry>
        <mesh filename="package://kuka_lwr_description/meshes/arm/convex/arm_segment_a_convex.stl"/>
      </geometry>
    </collision>
  </link>
  <gazebo reference="lwr_arm_link_1">
    <material value="kuka-lwr.material"/>
  </gazebo>
  <transmission name="lwr_arm_trans_0" type="pr2_mechanism_model/SimpleTransmission">
    <actuator name="lwr_arm_motor_0"/>
    <joint name="lwr_arm_joint_0"/>
    <mechanicalReduction>1.0</mechanicalReduction>
  </transmission>
  <joint name="lwr_arm_joint_1" type="revolute">
    <origin rpy="0 0 0" xyz="0 0 0.20"/>
    <axis xyz="0 -1 0"/>
    <limit effort="306" lower="-2.09439510239" upper="2.09439510239" velocity="1.91986217719"/>
    <safety_controller k_position="100" k_velocity="2" soft_lower_limit="-2.05948851735" soft_upper_limit="2.05948851735"/>
    <dynamics damping="0.1"/>
    <parent link="lwr_arm_link_1"/>
    <child link="lwr_arm_link_2"/>
  </joint>
  <link name="lwr_arm_link_2">
    <inertial>
      <mass value="2.0"/>
      <origin rpy="0 0 0" xyz="0 0.06 0.07"/>
      <inertia ixx="0.0136666666667" ixy="0" ixz="0" iyy="0.003" iyz="0" izz="0.0118666666667"/>
    </inertial>
    <visual>
      <origin rpy="3.14159265359 0 3.14159265359" xyz="0 0 0.2"/>
      <geometry>
        <mesh filename="package://kuka_lwr_description/meshes/arm/arm_segment_b.stl"/>
      </geometry>
      <material name="Orange"/>
    </visual>
    <collision>
      <origin rpy="3.14159265359 0 3.14159265359" xyz="0 0 0.2"/>
      <geometry>
        <mesh filename="package://kuka_lwr_description/meshes/arm/convex/arm_segment_b_convex.stl"/>
      </geometry>
    </collision>
  </link>
  <gazebo reference="lwr_arm_link_2">
    <material value="kuka-lwr.material"/>
  </gazebo>
  <transmission name="lwr_arm_trans_1" type="pr2_mechanism_model/SimpleTransmission">
    <actuator name="lwr_arm_motor_1"/>
    <joint name="lwr_arm_joint_1"/>
    <mechanicalReduction>1.0</mechanicalReduction>
  </transmission>
  <joint name="lwr_arm_joint_2" type="revolute">
    <origin rpy="0 0 0" xyz="0 0 0.20"/>
    <axis xyz="0 0 1"/>
    <limit effort="204" lower="-2.96705972839" upper="2.96705972839" velocity="2.26892802759"/>
    <safety_controller k_position="100" k_velocity="2" soft_lower_limit="-2.93215314335" soft_upper_limit="2.93215314335"/>
    <dynamics damping="0.1"/>
    <parent link="lwr_arm_link_2"/>
    <child link="lwr_arm_link_3"/>
  </joint>
  <link name="lwr_arm_link_3">
    <inertial>
      <mass value="2.0"/>
      <origin rpy="0 0 0" xyz="0 0.06 0.130"/>
      <inertia ixx="0.0136666666667" ixy="0" ixz="0" iyy="0.003" iyz="0" izz="0.0118666666667"/>
    </inertial>
    <visual>
      <origin rpy="0 0 0" xyz="0 0 0"/>
      <geometry>
        <mesh filename="package://kuka_lwr_description/meshes/arm/arm_segment_a.stl"/>
      </geometry>
      <material name="Orange"/>
    </visual>
    <collision>
      <origin rpy="0 0 0" xyz="0 0 0"/>
      <geometry>
        <mesh filename="package://kuka_lwr_description/meshes/arm/convex/arm_segment_a_convex.stl"/>
      </geometry>
    </collision>
  </link>
  <gazebo reference="lwr_arm_link_3">
    <material value="kuka-lwr.material"/>
  </gazebo>
  <transmission name="lwr_arm_trans_2" type="pr2_mechanism_model/SimpleTransmission">
    <actuator name="lwr_arm_motor_2"/>
    <joint name="lwr_arm_joint_2"/>
    <mechanicalReduction>1.0</mechanicalReduction>
  </transmission>
  <joint name="lwr_arm_joint_3" type="revolute">
    <origin rpy="0 0 0" xyz="0 0 0.20"/>
    <axis xyz="0 1 0"/>
    <limit effort="306" lower="-2.09439510239" upper="2.09439510239" velocity="2.26892802759"/>
    <safety_controller k_position="100" k_velocity="2" soft_lower_limit="-2.05948851735" soft_upper_limit="2.05948851735"/>
    <dynamics damping="0.1"/>
    <parent link="lwr_arm_link_3"/>
    <child link="lwr_arm_link_4"/>
  </joint>
  <link name="lwr_arm_link_4">
    <inertial>
      <mass value="2.0"/>
      <origin rpy="0 0 0" xyz="0 -0.06 0.07"/>
      <inertia ixx="0.0136666666667" ixy="0" ixz="0" iyy="0.003" iyz="0" izz="0.0118666666667"/>
    </inertial>
    <visual>
      <origin rpy="0 3.14159265359 3.14159265359" xyz="0 0 0.2"/>
      <geometry>
        <mesh filename="package://kuka_lwr_description/meshes/arm/arm_segment_b.stl"/>
      </geometry>
      <material name="Orange"/>
    </visual>
    <collision>
      <origin rpy="0 3.14159265359 3.14159265359" xyz="0 0 0.2"/>
      <geometry>
        <mesh filename="package://kuka_lwr_description/meshes/arm/convex/arm_segment_b_convex.stl"/>
      </geometry>
    </collision>
  </link>
  <gazebo reference="lwr_arm_link_4">
    <material value="kuka-lwr.material"/>
  </gazebo>
  <transmission name="lwr_arm_trans_3" type="pr2_mechanism_model/SimpleTransmission">
    <actuator name="lwr_arm_motor_3"/>
    <joint name="lwr_arm_joint_3"/>
    <mechanicalReduction>1.0</mechanicalReduction>
  </transmission>
  <joint name="lwr_arm_joint_4" type="revolute">
    <origin rpy="0 0 0" xyz="0 0 0.20"/>
    <axis xyz="0 0 1"/>
    <limit effort="204" lower="-2.96705972839" upper="2.96705972839" velocity="2.26892802759"/>
    <safety_controller k_position="100" k_velocity="2" soft_lower_limit="-2.93215314335" soft_upper_limit="2.93215314335"/>
    <dynamics damping="0.1"/>
    <parent link="lwr_arm_link_4"/>
    <child link="lwr_arm_link_5"/>
  </joint>
  <link name="lwr_arm_link_5">
    <inertial>
      <mass value="2.0"/>
      <origin rpy="0 0 0" xyz="0 0 0.124"/>
      <inertia ixx="0.0126506666667" ixy="0" ixz="0" iyy="0.003" iyz="0" izz="0.0108506666667"/>
    </inertial>
    <visual>
      <origin rpy="0 0 3.14159265359" xyz="0 0 0"/>
      <geometry name="lwr_arm_5_geom">
        <mesh filename="package://kuka_lwr_description/meshes/arm/arm_segment_last.stl"/>
      </geometry>
      <material name="Orange"/>
    </visual>
    <collision>
      <origin rpy="0 0 3.14159265359" xyz="0 0 0"/>
      <geometry>
        <mesh filename="package://kuka_lwr_description/meshes/arm/convex/arm_segment_last_convex.stl"/>
      </geometry>
    </collision>
  </link>
  <gazebo reference="lwr_arm_link_5">
    <material value="kuka-lwr.material"/>
  </gazebo>
  <transmission name="lwr_arm_trans_4" type="pr2_mechanism_model/SimpleTransmission">
    <actuator name="lwr_arm_motor_4"/>
    <joint name="lwr_arm_joint_4"/>
    <mechanicalReduction>1.0</mechanicalReduction>
  </transmission>
  <joint name="lwr_arm_joint_5" type="revolute">
    <origin rpy="0 0 0" xyz="0 0 0.19"/>
    <axis xyz="0 -1 0"/>
    <limit effort="306" lower="-2.09439510239" upper="2.09439510239" velocity="3.14159265359"/>
    <safety_controller k_position="100" k_velocity="2" soft_lower_limit="-2.05948851735" soft_upper_limit="2.05948851735"/>
    <dynamics damping="0.1"/>
    <parent link="lwr_arm_link_5"/>
    <child link="lwr_arm_link_6"/>
  </joint>
  <link name="lwr_arm_link_6">
    <inertial>
      <mass value="2.0"/>
      <origin rpy="0 0 0" xyz="0 0 0.0625"/>
      <inertia ixx="0.00520833333333" ixy="0" ixz="0" iyy="0.00520833333333" iyz="0" izz="0.00520833333333"/>
    </inertial>
    <visual>
      <origin rpy="0 0 3.14159265359" xyz="0 0 0"/>
      <geometry>
        <mesh filename="package://kuka_lwr_description/meshes/arm/arm_wrist.stl"/>
      </geometry>
      <material name="Grey"/>
    </visual>
    <collision>
      <origin rpy="0 0 3.14159265359" xyz="0 0 0"/>
      <geometry>
        <mesh filename="package://kuka_lwr_description/meshes/arm/convex/arm_wrist_convex.stl"/>
      </geometry>
    </collision>
  </link>
  <gazebo reference="lwr_arm_link_6">
    <material value="kuka-lwr.material"/>
  </gazebo>
  <transmission name="lwr_arm_trans_5" type="pr2_mechanism_model/SimpleTransmission">
    <actuator name="lwr_arm_motor_5"/>
    <joint name="lwr_arm_joint_5"/>
    <mechanicalReduction>1.0</mechanicalReduction>
  </transmission>
  <joint name="lwr_arm_joint_6" type="revolute">
    <origin rpy="0 0 0" xyz="0 0 0.078"/>
    <axis xyz="0 0 1"/>
    <limit effort="204" lower="-2.96705972839" upper="2.96705972839" velocity="3.14159265359"/>
    <safety_controller k_position="100" k_velocity="2" soft_lower_limit="-2.93215314335" soft_upper_limit="2.93215314335"/>
    <dynamics damping="0.1"/>
    <parent link="lwr_arm_link_6"/>
    <child link="lwr_arm_link_7"/>
  </joint>
  <link name="lwr_arm_link_7">
    <inertial>
      <mass value="2.0"/>
      <origin xyz="0 0 0"/>
      <inertia ixx="0.333333333333" ixy="0" ixz="0" iyy="0.333333333333" iyz="0" izz="0.333333333333"/>
    </inertial>
    <visual>
      <origin rpy="0 0 2.35619449019" xyz="0 0 0"/>
      <geometry>
        <mesh filename="package://kuka_lwr_description/meshes/arm/arm_flanche_angle.stl"/>
      </geometry>
      <material name="Black"/>
    </visual>
    <collision>
      <origin rpy="0 0 2.35619449019" xyz="0 0 0"/>
      <geometry>
        <mesh filename="package://kuka_lwr_description/meshes/arm/convex/arm_flanche_angle_convex.stl"/>
      </geometry>
    </collision>
  </link>
  <gazebo reference="lwr_arm_link_7">
    <material value="kuka-lwr.material"/>
  </gazebo>
  <transmission name="lwr_arm_trans_6" type="pr2_mechanism_model/SimpleTransmission">
    <actuator name="lwr_arm_motor_6"/>
    <joint name="lwr_arm_joint_6"/>
    <mechanicalReduction>1.0</mechanicalReduction>
  </transmission>
  <joint name="lwr_arm_hand_fixed_joint" type="fixed">
    <origin rpy="1.57079632679 0 5.49778714378" xyz="-0.075 -0.075 -0.094"/>
    <parent link="lwr_arm_link_7"/>
    <child link="lwr_arm_hand_link"/>
  </joint>
  <link name="lwr_arm_hand_link"/>
</robot>

