<?xml version="1.0" ?>
<!-- =================================================================================== -->
<!-- |    This document was autogenerated by xacro from kia_setup.urdf.xacro           | -->
<!-- |    EDITING THIS FILE BY HAND IS NOT RECOMMENDED                                 | -->
<!-- =================================================================================== -->
<robot name="two_arms">
  <!--  Configuration properties   -->
  <!-- Create the world link -->
  <!-- The world frame concides with the bottom center of the torso  -->
  <link name="world"/>
  <link name="world_left"/>
  <joint name="world_left_joint" type="fixed">
    <!-- Calibration with Fede -->
    <!-- <origin xyz="0.00425911 0.00130823 -0.0066479" rpy="${-0.0008} ${-0.0050} ${-0.01565}"/> -->
    <!-- 9th March -->
    <!-- <origin xyz="0.008659 0.012155 -0.0106208" rpy="${0.0046714} ${-0.0103363} ${-0.0179148}"/> -->
    <!-- 10th March -->
    <!-- <origin xyz="-0.0092469 0.0233883 -0.0021766" rpy="${0.01540014} ${0.005644} ${-0.0144132}"/> -->
    <!-- Pickit 10th March -->
    <!-- <origin xyz="0.0001637 0.02336629 -0.005245" rpy="${0.0117911} ${0.000623} ${-0.0153726}"/> -->
    <!-- <origin xyz="0.000197056 -0.0235992 0.005524" rpy="${-0.011799} ${-0.00044219} ${0.0153788}"/> -->
    <!-- <origin xyz="0.0001637 0.02336629 -0.005245" rpy="${0.0117911} ${0.000623} ${-0.0153726}"/> -->
    <!-- Calibration with Pickit -->
    <!-- <origin xyz="0.00 -0.00519 -0.01034" rpy="${-0.0001735} ${-0.0024621} ${0.00172}"/> -->
    <!-- Calibration Lander -->
    <!-- <origin xyz="-0.02165132 -0.0432277 0.0049708" rpy="${0.01553728} ${0.01805164} ${-0.02646349}"/> -->
    <!-- Calibration Cristian -->
    <origin rpy="0.0156 0.01805164 -0.02656" xyz="-0.021587 0.032 0.0041"/>
    <!-- <origin xyz="0.0 0.0 0.0" rpy="${0.0} ${0.0} ${0.0}"/> -->
    <parent link="world"/>
    <child link="world_left"/>
  </joint>
  <!-- ************ ROBOT AND BASE **********     -->
  <!-- Create the torso link -->
  <joint name="iiwa1_torso_joint" type="fixed">
    <origin rpy="0 0 -1.5708" xyz="0 0 1.33118"/>
    <parent link="world"/>
    <child link="iiwa1_torso_link"/>
  </joint>
  <link name="iiwa1_torso_link">
    <visual>
      <origin rpy="0 0 0" xyz="0 0 0.0"/>
      <geometry>
        <mesh filename="package://planar_contour_following/robot_description/meshes/torso.stl" scale="0.001 0.001 0.001"/>
      </geometry>
      <material name="Gold"/>
    </visual>
  </link>
  <joint name="iiwa2_torso_joint" type="fixed">
    <parent link="world_left"/>
    <origin rpy="0 0 -1.5708" xyz="0 0 1.33118"/>
    <child link="iiwa2_torso_link"/>
  </joint>
  <link name="iiwa2_torso_link">
    </link>
  <material name="Black">
    <color rgba="0.0 0.0 0.0 1.0"/>
  </material>
  <material name="Blue">
    <color rgba="0.0 0.0 0.8 1.0"/>
  </material>
  <material name="Green">
    <color rgba="0.0 0.8 0.0 1.0"/>
  </material>
  <material name="Yellow">
    <color rgba="0.6 0.6 0 1.0"/>
  </material>
  <material name="Orange">
    <color rgba="1.0 0.4235294117647059 0.0392156862745098 1.0"/>
  </material>
  <material name="Brown">
    <color rgba="0.8705882352941177 0.8117647058823529 0.7647058823529411 1.0"/>
  </material>
  <material name="Brown_table">
    <color rgba="0.5450980392156862 0.27058823529411763 0.07450980392156863 1"/>
  </material>
  <material name="Red">
    <color rgba="0.8 0.0 0.0 1.0"/>
  </material>
  <material name="White">
    <color rgba="1.0 1.0 1.0 1.0"/>
  </material>
  <material name="Soft Grey">
    <color rgba=".4 .4 .4 1"/>
  </material>
  <material name="Dark Grey">
    <color rgba=".2 .2 .2 1"/>
  </material>
  <material name="Bright Grey">
    <color rgba=".6 .6 .6 1"/>
  </material>
  <material name="Beige">
    <color rgba="0.8705882352941177 0.7215686274509804 0.5294117647058824 1"/>
  </material>
  <material name="Gold">
    <color rgba="0.5176470588235295 0.4117647058823529 0.19215686274509805 1"/>
  </material>
  <!--<xacro:include filename="$(find planar_contour_following)/robot_description/urdf/dual_iiwa/flexfellow.xacro" /> -->
  <!--joint between {parent} and link_0-->
  <joint name="iiwa1_torso_link_iiwa1_joint" type="fixed">
    <origin rpy="0.785398 0.0  1.5708" xyz="0.11127 0.0 -0.07513"/>
    <parent link="iiwa1_torso_link"/>
    <child link="iiwa1_link_0"/>
  </joint>
  <link name="iiwa1_link_0">
    <inertial>
      <origin rpy="0 0 0" xyz="-0.1 0 0.07"/>
      <mass value="5"/>
      <inertia ixx="0.05" ixy="0" ixz="0" iyy="0.06" iyz="0" izz="0.03"/>
    </inertial>
    <visual>
      <origin rpy="0 0 0" xyz="0 0 0"/>
      <geometry>
        <mesh filename="package://lbr_iiwa_description/meshes/link_0.stl"/>
      </geometry>
      <material name="Soft Grey"/>
    </visual>
    <collision>
      <origin rpy="0 0 0" xyz="0 0 0"/>
      <geometry>
        <mesh filename="package://planar_contour_following/robot_description/meshes/collision/iiwa14/link_0_capsule.obj"/>
      </geometry>
      <material name="Grey"/>
    </collision>
    <self_collision_checking>
      <origin rpy="0 0 0" xyz="0 0 0"/>
      <geometry>
        <capsule length="0.25" radius="0.15"/>
      </geometry>
    </self_collision_checking>
  </link>
  <!-- joint between link_0 and link_1 -->
  <joint name="iiwa1_joint_1" type="revolute">
    <parent link="iiwa1_link_0"/>
    <child link="iiwa1_link_1"/>
    <origin rpy="0 0 0" xyz="0 0 0.1575"/>
    <axis xyz="0 0 1"/>
    <limit effort="300" lower="-2.9146998508305306" upper="2.9146998508305306" velocity="1"/>
    <safety_controller k_position="100" k_velocity="2" soft_lower_limit="-2.9321531433504737" soft_upper_limit="2.9321531433504737"/>
    <dynamics damping="0.5"/>
  </joint>
  <link name="iiwa1_link_1">
    <inertial>
      <origin rpy="0 0 0" xyz="0 -0.03 0.12"/>
      <mass value="4"/>
      <inertia ixx="0.1" ixy="0" ixz="0" iyy="0.09" iyz="0" izz="0.02"/>
    </inertial>
    <visual>
      <origin rpy="0 0 0" xyz="0 0 0"/>
      <geometry>
        <mesh filename="package://lbr_iiwa_description/meshes/link_1.stl"/>
      </geometry>
      <material name="Orange"/>
    </visual>
    <collision>
      <origin rpy="0 0 0" xyz="0 0 0"/>
      <geometry>
        <mesh filename="package://planar_contour_following/robot_description/meshes/collision/iiwa14/link_1_capsule.obj"/>
      </geometry>
      <material name="Orange"/>
    </collision>
  </link>
  <!-- joint between link_1 and link_2 -->
  <joint name="iiwa1_joint_2" type="revolute">
    <parent link="iiwa1_link_1"/>
    <child link="iiwa1_link_2"/>
    <origin rpy="1.5707963267948966   0 3.141592653589793" xyz="0 0 0.2025"/>
    <axis xyz="0 0 1"/>
    <limit effort="300" lower="-2.0420352248333655" upper="2.0420352248333655" velocity="1"/>
    <safety_controller k_position="100" k_velocity="2" soft_lower_limit="-2.0594885173533086" soft_upper_limit="2.0594885173533086"/>
    <dynamics damping="0.5"/>
  </joint>
  <link name="iiwa1_link_2">
    <inertial>
      <origin rpy="0 0 0" xyz="0.0003 0.059 0.042"/>
      <mass value="4"/>
      <inertia ixx="0.05" ixy="0" ixz="0" iyy="0.018" iyz="0" izz="0.044"/>
    </inertial>
    <visual>
      <origin rpy="0 0 0" xyz="0 0 0"/>
      <geometry>
        <mesh filename="package://lbr_iiwa_description/meshes/link_2.stl"/>
      </geometry>
      <material name="Orange"/>
    </visual>
    <collision>
      <origin rpy="0 0 0" xyz="0 0 0"/>
      <geometry>
        <mesh filename="package://planar_contour_following/robot_description/meshes/collision/iiwa14/link_2_capsule.obj"/>
      </geometry>
      <material name="Orange"/>
    </collision>
  </link>
  <!-- joint between link_2 and link_3 -->
  <joint name="iiwa1_joint_3" type="revolute">
    <parent link="iiwa1_link_2"/>
    <child link="iiwa1_link_3"/>
    <origin rpy="1.5707963267948966 0 3.141592653589793" xyz="0 0.2045 0"/>
    <axis xyz="0 0 1"/>
    <limit effort="300" lower="-2.9146998508305306" upper="2.9146998508305306" velocity="1"/>
    <safety_controller k_position="100" k_velocity="2" soft_lower_limit="-2.9321531433504737" soft_upper_limit="2.9321531433504737"/>
    <dynamics damping="0.5"/>
  </joint>
  <link name="iiwa1_link_3">
    <inertial>
      <origin rpy="0 0 0" xyz="0 0.03 0.13"/>
      <mass value="3"/>
      <inertia ixx="0.08" ixy="0" ixz="0" iyy="0.075" iyz="0" izz="0.01"/>
    </inertial>
    <visual>
      <origin rpy="0 0 0" xyz="0 0 0"/>
      <geometry>
        <mesh filename="package://lbr_iiwa_description/meshes/link_3.stl"/>
      </geometry>
      <material name="Orange"/>
    </visual>
    <collision>
      <origin rpy="0 0 0" xyz="0 0 0"/>
      <geometry>
        <mesh filename="package://planar_contour_following/robot_description/meshes/collision/iiwa14/link_3_capsule.obj"/>
      </geometry>
      <material name="Orange"/>
    </collision>
  </link>
  <!-- joint between link_3 and link_4 -->
  <joint name="iiwa1_joint_4" type="revolute">
    <parent link="iiwa1_link_3"/>
    <child link="iiwa1_link_4"/>
    <origin rpy="1.5707963267948966 0 0" xyz="0 0 0.2155"/>
    <axis xyz="0 0 1"/>
    <limit effort="300" lower="-2.0420352248333655" upper="2.0420352248333655" velocity="1"/>
    <safety_controller k_position="100" k_velocity="2" soft_lower_limit="-2.0594885173533086" soft_upper_limit="2.0594885173533086"/>
    <dynamics damping="0.5"/>
  </joint>
  <link name="iiwa1_link_4">
    <inertial>
      <origin rpy="0 0 0" xyz="0 0.067 0.034"/>
      <mass value="2.7"/>
      <inertia ixx="0.03" ixy="0" ixz="0" iyy="0.01" iyz="0" izz="0.029"/>
    </inertial>
    <visual>
      <origin rpy="0 0 0" xyz="0 0 0"/>
      <geometry>
        <mesh filename="package://lbr_iiwa_description/meshes/link_4.stl"/>
      </geometry>
      <material name="Orange"/>
    </visual>
    <collision>
      <origin rpy="0 0 0" xyz="0 0 0"/>
      <geometry>
        <mesh filename="package://planar_contour_following/robot_description/meshes/collision/iiwa14/link_4_capsule.obj"/>
      </geometry>
      <material name="Orange"/>
    </collision>
  </link>
  <!-- joint between link_4 and link_5 -->
  <joint name="iiwa1_joint_5" type="revolute">
    <parent link="iiwa1_link_4"/>
    <child link="iiwa1_link_5"/>
    <origin rpy="-1.5707963267948966 3.141592653589793 0" xyz="0 0.1845 0"/>
    <axis xyz="0 0 1"/>
    <limit effort="300" lower="-2.9146998508305306" upper="2.9146998508305306" velocity="1"/>
    <safety_controller k_position="100" k_velocity="2" soft_lower_limit="-2.9321531433504737" soft_upper_limit="2.9321531433504737"/>
    <dynamics damping="0.5"/>
  </joint>
  <link name="iiwa1_link_5">
    <inertial>
      <origin rpy="0 0 0" xyz="0.0001 0.021 0.076"/>
      <mass value="1.7"/>
      <inertia ixx="0.02" ixy="0" ixz="0" iyy="0.018" iyz="0" izz="0.005"/>
    </inertial>
    <visual>
      <origin rpy="0 0 0" xyz="0 0 0"/>
      <geometry>
        <mesh filename="package://lbr_iiwa_description/meshes/link_5.stl"/>
      </geometry>
      <material name="Orange"/>
    </visual>
    <collision>
      <origin rpy="0 0 0" xyz="0 0 0"/>
      <geometry>
        <mesh filename="package://planar_contour_following/robot_description/meshes/collision/iiwa14/link_5_capsule.obj"/>
      </geometry>
      <material name="Orange"/>
    </collision>
  </link>
  <!-- joint between link_5 and link_6 -->
  <joint name="iiwa1_joint_6" type="revolute">
    <parent link="iiwa1_link_5"/>
    <child link="iiwa1_link_6"/>
    <origin rpy="1.5707963267948966 0 0" xyz="0 0 0.2155"/>
    <axis xyz="0 0 1"/>
    <limit effort="300" lower="-2.0420352248333655" upper="2.0420352248333655" velocity="1"/>
    <safety_controller k_position="100" k_velocity="2" soft_lower_limit="-2.0594885173533086" soft_upper_limit="2.0594885173533086"/>
    <dynamics damping="0.5"/>
  </joint>
  <link name="iiwa1_link_6">
    <inertial>
      <origin rpy="0 0 0" xyz="0 0.0006 0.0004"/>
      <mass value="1.8"/>
      <inertia ixx="0.005" ixy="0" ixz="0" iyy="0.0036" iyz="0" izz="0.0047"/>
    </inertial>
    <visual>
      <origin rpy="0 0 0" xyz="0 0 0"/>
      <geometry>
        <mesh filename="package://lbr_iiwa_description/meshes/link_6.stl"/>
      </geometry>
      <material name="Orange"/>
    </visual>
    <collision>
      <origin rpy="0 0 0" xyz="0 0 0"/>
      <geometry>
        <mesh filename="package://planar_contour_following/robot_description/meshes/collision/iiwa14/link_6_capsule.obj"/>
      </geometry>
      <material name="Orange"/>
    </collision>
  </link>
  <!-- joint between link_6 and link_7 -->
  <joint name="iiwa1_joint_7" type="revolute">
    <parent link="iiwa1_link_6"/>
    <child link="iiwa1_link_7"/>
    <origin rpy="-1.5707963267948966 3.141592653589793 0" xyz="0 0.081 0"/>
    <axis xyz="0 0 1"/>
    <limit effort="300" lower="-3.0019663134302466" upper="3.0019663134302466" velocity="1"/>
    <safety_controller k_position="100" k_velocity="2" soft_lower_limit="-3.01941960595019" soft_upper_limit="3.01941960595019"/>
    <dynamics damping="0.5"/>
  </joint>
  <link name="iiwa1_link_7">
    <inertial>
      <origin rpy="0 0 0" xyz="0 0 0.02"/>
      <mass value="0.3"/>
      <inertia ixx="0.001" ixy="0" ixz="0" iyy="0.001" iyz="0" izz="0.001"/>
    </inertial>
    <visual>
      <origin rpy="0 0 0" xyz="0 0 0"/>
      <geometry>
        <mesh filename="package://lbr_iiwa_description/meshes/link_7.stl"/>
      </geometry>
      <material name="Soft Grey"/>
    </visual>
    <collision>
      <origin rpy="0 0 0" xyz="0 0 0"/>
      <geometry>
        <mesh filename="package://planar_contour_following/robot_description/meshes/collision/iiwa14/link_7_capsule.obj"/>
      </geometry>
      <material name="Grey"/>
    </collision>
  </link>
  <joint name="iiwa1_joint_ee" type="fixed">
    <parent link="iiwa1_link_7"/>
    <child link="iiwa1_link_ee"/>
    <origin rpy="0 -1.5707963267948966 0" xyz="0 0 0.045"/>
  </joint>
  <link name="iiwa1_link_ee">
    </link>
  <joint name="iiwa1_joint_ee_kuka" type="fixed">
    <parent link="iiwa1_link_7"/>
    <child link="iiwa1_link_ee_kuka"/>
    <origin rpy="3.141592653589793 3.141592653589793 3.141592653589793" xyz="0 0 0.045"/>
    <axis xyz="0 0 1"/>
  </joint>
  <link name="iiwa1_link_ee_kuka">
    </link>
  <joint name="iiwa1_joint_ee_pneumatic" type="fixed">
    <parent link="iiwa1_link_ee_kuka"/>
    <child link="iiwa1_link_ee_pneumatic"/>
    <origin rpy="0 0 0" xyz="0 0 0.026"/>
  </joint>
  <link name="iiwa1_link_ee_pneumatic">
    </link>
  <!--joint between {parent} and link_0-->
  <joint name="iiwa2_torso_link_iiwa2_joint" type="fixed">
    <origin rpy="-0.785398 0.0  1.5708" xyz="-0.11127 0.0 -0.07513"/>
    <parent link="iiwa2_torso_link"/>
    <child link="iiwa2_link_0"/>
  </joint>
  <link name="iiwa2_link_0">
    <inertial>
      <origin rpy="0 0 0" xyz="-0.1 0 0.07"/>
      <mass value="5"/>
      <inertia ixx="0.05" ixy="0" ixz="0" iyy="0.06" iyz="0" izz="0.03"/>
    </inertial>
    <visual>
      <origin rpy="0 0 0" xyz="0 0 0"/>
      <geometry>
        <mesh filename="package://lbr_iiwa_description/meshes/link_0.stl"/>
      </geometry>
      <material name="Soft Grey"/>
    </visual>
    <collision>
      <origin rpy="0 0 0" xyz="0 0 0"/>
      <geometry>
        <mesh filename="package://planar_contour_following/robot_description/meshes/collision/iiwa14/link_0_capsule.obj"/>
      </geometry>
      <material name="Grey"/>
    </collision>
    <self_collision_checking>
      <origin rpy="0 0 0" xyz="0 0 0"/>
      <geometry>
        <capsule length="0.25" radius="0.15"/>
      </geometry>
    </self_collision_checking>
  </link>
  <!-- joint between link_0 and link_1 -->
  <joint name="iiwa2_joint_1" type="revolute">
    <parent link="iiwa2_link_0"/>
    <child link="iiwa2_link_1"/>
    <origin rpy="0 0 0" xyz="0 0 0.1575"/>
    <axis xyz="0 0 1"/>
    <limit effort="300" lower="-2.9146998508305306" upper="2.9146998508305306" velocity="1"/>
    <safety_controller k_position="100" k_velocity="2" soft_lower_limit="-2.9321531433504737" soft_upper_limit="2.9321531433504737"/>
    <dynamics damping="0.5"/>
  </joint>
  <link name="iiwa2_link_1">
    <inertial>
      <origin rpy="0 0 0" xyz="0 -0.03 0.12"/>
      <mass value="4"/>
      <inertia ixx="0.1" ixy="0" ixz="0" iyy="0.09" iyz="0" izz="0.02"/>
    </inertial>
    <visual>
      <origin rpy="0 0 0" xyz="0 0 0"/>
      <geometry>
        <mesh filename="package://lbr_iiwa_description/meshes/link_1.stl"/>
      </geometry>
      <material name="Orange"/>
    </visual>
    <collision>
      <origin rpy="0 0 0" xyz="0 0 0"/>
      <geometry>
        <mesh filename="package://planar_contour_following/robot_description/meshes/collision/iiwa14/link_1_capsule.obj"/>
      </geometry>
      <material name="Orange"/>
    </collision>
  </link>
  <!-- joint between link_1 and link_2 -->
  <joint name="iiwa2_joint_2" type="revolute">
    <parent link="iiwa2_link_1"/>
    <child link="iiwa2_link_2"/>
    <origin rpy="1.5707963267948966   0 3.141592653589793" xyz="0 0 0.2025"/>
    <axis xyz="0 0 1"/>
    <limit effort="300" lower="-2.0420352248333655" upper="2.0420352248333655" velocity="1"/>
    <safety_controller k_position="100" k_velocity="2" soft_lower_limit="-2.0594885173533086" soft_upper_limit="2.0594885173533086"/>
    <dynamics damping="0.5"/>
  </joint>
  <link name="iiwa2_link_2">
    <inertial>
      <origin rpy="0 0 0" xyz="0.0003 0.059 0.042"/>
      <mass value="4"/>
      <inertia ixx="0.05" ixy="0" ixz="0" iyy="0.018" iyz="0" izz="0.044"/>
    </inertial>
    <visual>
      <origin rpy="0 0 0" xyz="0 0 0"/>
      <geometry>
        <mesh filename="package://lbr_iiwa_description/meshes/link_2.stl"/>
      </geometry>
      <material name="Orange"/>
    </visual>
    <collision>
      <origin rpy="0 0 0" xyz="0 0 0"/>
      <geometry>
        <mesh filename="package://planar_contour_following/robot_description/meshes/collision/iiwa14/link_2_capsule.obj"/>
      </geometry>
      <material name="Orange"/>
    </collision>
  </link>
  <!-- joint between link_2 and link_3 -->
  <joint name="iiwa2_joint_3" type="revolute">
    <parent link="iiwa2_link_2"/>
    <child link="iiwa2_link_3"/>
    <origin rpy="1.5707963267948966 0 3.141592653589793" xyz="0 0.2045 0"/>
    <axis xyz="0 0 1"/>
    <limit effort="300" lower="-2.9146998508305306" upper="2.9146998508305306" velocity="1"/>
    <safety_controller k_position="100" k_velocity="2" soft_lower_limit="-2.9321531433504737" soft_upper_limit="2.9321531433504737"/>
    <dynamics damping="0.5"/>
  </joint>
  <link name="iiwa2_link_3">
    <inertial>
      <origin rpy="0 0 0" xyz="0 0.03 0.13"/>
      <mass value="3"/>
      <inertia ixx="0.08" ixy="0" ixz="0" iyy="0.075" iyz="0" izz="0.01"/>
    </inertial>
    <visual>
      <origin rpy="0 0 0" xyz="0 0 0"/>
      <geometry>
        <mesh filename="package://lbr_iiwa_description/meshes/link_3.stl"/>
      </geometry>
      <material name="Orange"/>
    </visual>
    <collision>
      <origin rpy="0 0 0" xyz="0 0 0"/>
      <geometry>
        <mesh filename="package://planar_contour_following/robot_description/meshes/collision/iiwa14/link_3_capsule.obj"/>
      </geometry>
      <material name="Orange"/>
    </collision>
  </link>
  <!-- joint between link_3 and link_4 -->
  <joint name="iiwa2_joint_4" type="revolute">
    <parent link="iiwa2_link_3"/>
    <child link="iiwa2_link_4"/>
    <origin rpy="1.5707963267948966 0 0" xyz="0 0 0.2155"/>
    <axis xyz="0 0 1"/>
    <limit effort="300" lower="-2.0420352248333655" upper="2.0420352248333655" velocity="1"/>
    <safety_controller k_position="100" k_velocity="2" soft_lower_limit="-2.0594885173533086" soft_upper_limit="2.0594885173533086"/>
    <dynamics damping="0.5"/>
  </joint>
  <link name="iiwa2_link_4">
    <inertial>
      <origin rpy="0 0 0" xyz="0 0.067 0.034"/>
      <mass value="2.7"/>
      <inertia ixx="0.03" ixy="0" ixz="0" iyy="0.01" iyz="0" izz="0.029"/>
    </inertial>
    <visual>
      <origin rpy="0 0 0" xyz="0 0 0"/>
      <geometry>
        <mesh filename="package://lbr_iiwa_description/meshes/link_4.stl"/>
      </geometry>
      <material name="Orange"/>
    </visual>
    <collision>
      <origin rpy="0 0 0" xyz="0 0 0"/>
      <geometry>
        <mesh filename="package://planar_contour_following/robot_description/meshes/collision/iiwa14/link_4_capsule.obj"/>
      </geometry>
      <material name="Orange"/>
    </collision>
  </link>
  <!-- joint between link_4 and link_5 -->
  <joint name="iiwa2_joint_5" type="revolute">
    <parent link="iiwa2_link_4"/>
    <child link="iiwa2_link_5"/>
    <origin rpy="-1.5707963267948966 3.141592653589793 0" xyz="0 0.1845 0"/>
    <axis xyz="0 0 1"/>
    <limit effort="300" lower="-2.9146998508305306" upper="2.9146998508305306" velocity="1"/>
    <safety_controller k_position="100" k_velocity="2" soft_lower_limit="-2.9321531433504737" soft_upper_limit="2.9321531433504737"/>
    <dynamics damping="0.5"/>
  </joint>
  <link name="iiwa2_link_5">
    <inertial>
      <origin rpy="0 0 0" xyz="0.0001 0.021 0.076"/>
      <mass value="1.7"/>
      <inertia ixx="0.02" ixy="0" ixz="0" iyy="0.018" iyz="0" izz="0.005"/>
    </inertial>
    <visual>
      <origin rpy="0 0 0" xyz="0 0 0"/>
      <geometry>
        <mesh filename="package://lbr_iiwa_description/meshes/link_5.stl"/>
      </geometry>
      <material name="Orange"/>
    </visual>
    <collision>
      <origin rpy="0 0 0" xyz="0 0 0"/>
      <geometry>
        <mesh filename="package://planar_contour_following/robot_description/meshes/collision/iiwa14/link_5_capsule.obj"/>
      </geometry>
      <material name="Orange"/>
    </collision>
  </link>
  <!-- joint between link_5 and link_6 -->
  <joint name="iiwa2_joint_6" type="revolute">
    <parent link="iiwa2_link_5"/>
    <child link="iiwa2_link_6"/>
    <origin rpy="1.5707963267948966 0 0" xyz="0 0 0.2155"/>
    <axis xyz="0 0 1"/>
    <limit effort="300" lower="-2.0420352248333655" upper="2.0420352248333655" velocity="1"/>
    <safety_controller k_position="100" k_velocity="2" soft_lower_limit="-2.0594885173533086" soft_upper_limit="2.0594885173533086"/>
    <dynamics damping="0.5"/>
  </joint>
  <link name="iiwa2_link_6">
    <inertial>
      <origin rpy="0 0 0" xyz="0 0.0006 0.0004"/>
      <mass value="1.8"/>
      <inertia ixx="0.005" ixy="0" ixz="0" iyy="0.0036" iyz="0" izz="0.0047"/>
    </inertial>
    <visual>
      <origin rpy="0 0 0" xyz="0 0 0"/>
      <geometry>
        <mesh filename="package://lbr_iiwa_description/meshes/link_6.stl"/>
      </geometry>
      <material name="Orange"/>
    </visual>
    <collision>
      <origin rpy="0 0 0" xyz="0 0 0"/>
      <geometry>
        <mesh filename="package://planar_contour_following/robot_description/meshes/collision/iiwa14/link_6_capsule.obj"/>
      </geometry>
      <material name="Orange"/>
    </collision>
  </link>
  <!-- joint between link_6 and link_7 -->
  <joint name="iiwa2_joint_7" type="revolute">
    <parent link="iiwa2_link_6"/>
    <child link="iiwa2_link_7"/>
    <origin rpy="-1.5707963267948966 3.141592653589793 0" xyz="0 0.081 0"/>
    <axis xyz="0 0 1"/>
    <limit effort="300" lower="-3.0019663134302466" upper="3.0019663134302466" velocity="1"/>
    <safety_controller k_position="100" k_velocity="2" soft_lower_limit="-3.01941960595019" soft_upper_limit="3.01941960595019"/>
    <dynamics damping="0.5"/>
  </joint>
  <link name="iiwa2_link_7">
    <inertial>
      <origin rpy="0 0 0" xyz="0 0 0.02"/>
      <mass value="0.3"/>
      <inertia ixx="0.001" ixy="0" ixz="0" iyy="0.001" iyz="0" izz="0.001"/>
    </inertial>
    <visual>
      <origin rpy="0 0 0" xyz="0 0 0"/>
      <geometry>
        <mesh filename="package://lbr_iiwa_description/meshes/link_7.stl"/>
      </geometry>
      <material name="Soft Grey"/>
    </visual>
    <collision>
      <origin rpy="0 0 0" xyz="0 0 0"/>
      <geometry>
        <mesh filename="package://planar_contour_following/robot_description/meshes/collision/iiwa14/link_7_capsule.obj"/>
      </geometry>
      <material name="Grey"/>
    </collision>
  </link>
  <joint name="iiwa2_joint_ee" type="fixed">
    <parent link="iiwa2_link_7"/>
    <child link="iiwa2_link_ee"/>
    <origin rpy="0 -1.5707963267948966 0" xyz="0 0 0.045"/>
  </joint>
  <link name="iiwa2_link_ee">
    </link>
  <joint name="iiwa2_joint_ee_kuka" type="fixed">
    <parent link="iiwa2_link_7"/>
    <child link="iiwa2_link_ee_kuka"/>
    <origin rpy="3.141592653589793 3.141592653589793 3.141592653589793" xyz="0 0 0.045"/>
    <axis xyz="0 0 1"/>
  </joint>
  <link name="iiwa2_link_ee_kuka">
    </link>
  <joint name="iiwa2_joint_ee_pneumatic" type="fixed">
    <parent link="iiwa2_link_ee_kuka"/>
    <child link="iiwa2_link_ee_pneumatic"/>
    <origin rpy="0 0 0" xyz="0 0 0.026"/>
  </joint>
  <link name="iiwa2_link_ee_pneumatic">
    </link>
  <!--<xacro:flexfellow parent="world_left"> -->
  <!--    <origin xyz="0.0 0.0 0.454" rpy="0.0 0.0 0.0"/> -->
  <!--</xacro:flexfellow> -->
  <!-- FT sensor right -->
  <!-- <link name="ft_sensor_frame_right"/> -->
  <joint name="ft_sensor_joint_right" type="fixed">
    <origin rpy="0 3.1416 -0.7854" xyz="0 0 0.0225"/>
    <parent link="iiwa1_link_ee_pneumatic"/>
    <child link="ft_sensor_frame_right"/>
  </joint>
  <link name="ft_sensor_frame_right">
    <visual>
      <geometry>
        <mesh filename="package://planar_contour_following/robot_description/meshes/load_cell_67.stl" scale=".001 .001 .001"/>
      </geometry>
      <material name="Blue">
        <color rgba="0 0 0.3 1"/>
      </material>
    </visual>
    <collision>
      <geometry>
        <mesh filename="package://planar_contour_following/robot_description/meshes/load_cell_67.stl" scale=".001 .001 .001"/>
      </geometry>
    </collision>
  </link>
  <!-- FT sensor left -->
  <link name="ft_sensor_frame_left"/>
  <joint name="ft_sensor_joint_left" type="fixed">
    <origin rpy="0 3.1416 -0.7854" xyz="0 0 0.0225"/>
    <parent link="iiwa2_link_ee_pneumatic"/>
    <child link="ft_sensor_frame_left"/>
  </joint>
  <!-- Small FT sensor left -->
  <!-- <link name="ft_sensor_frame_left"/>
  	<joint name="ft_sensor_joint_left" type="fixed">
  		<origin xyz="0 0 ${0.01 + 0.0315/2}" rpy="${0} ${3.1416} ${-3.1416/4}"/>
  		<parent link="iiwa2_link_ee_pneumatic"/>
  		<child link="ft_sensor_frame_left"/>
  	</joint> -->
  <!-- tool -->
  <joint name="tool_joint" type="fixed">
    <origin rpy="0 0 0" xyz="0 0 -0.0125"/>
    <parent link="ft_sensor_frame_right"/>
    <child link="tool_link"/>
  </joint>
  <link name="tool_link">
    <visual>
      <geometry>
        <mesh filename="package://planar_contour_following/robot_description/meshes/tool_short.stl" scale=".001 .001 .001"/>
      </geometry>
      <material name="gray">
        <color rgba="0.4 0.4 0.4 1"/>
      </material>
    </visual>
    <collision>
      <geometry>
        <mesh filename="package://planar_contour_following/robot_description/meshes/tool_short.stl" scale=".001 .001 .001"/>
      </geometry>
    </collision>
  </link>
  <!-- tcp -->
  <link name="tcp_link"/>
  <joint name="tcp_joint" type="fixed">
    <!--origin xyz="${-0.0028} ${0.0037} ${-0.1577}" rpy="${0} ${3.1416} ${-3.1416/4}"/> -->
    <origin rpy="0 0 0" xyz="0 0 -0.151"/>
    <!--for short tool without ASA-->
    <!-- <origin xyz="0 0 ${-0.286}" rpy="${0} ${3.1416} ${-3.1416/4}"/> for long tool -->
    <parent link="tool_link"/>
    <child link="tcp_link"/>
  </joint>
  <!-- ************ TABLE **********     -->
  <link name="table_link">
    <visual>
      <origin rpy="0 0 0" xyz="0 0 0.0"/>
      <geometry>
        <mesh filename="package://planar_contour_following/robot_description/meshes/table.stl" scale="0.001 0.001 0.001"/>
      </geometry>
      <material name="White"/>
    </visual>
  </link>
  <joint name="table_joint" type="fixed">
    <parent link="world"/>
    <origin rpy="1.5708 0 1.5708" xyz="0.7 0 0"/>
    <child link="table_link"/>
  </joint>
  <link name="connection_link">
    <visual>
      <origin rpy="0 0 0" xyz="0 0 0.0"/>
      <geometry>
        <mesh filename="package://planar_contour_following/robot_description/meshes/connection-ee-sensor.stl" scale="0.001 0.001 0.001"/>
      </geometry>
      <material name="gray">
        <color rgba="0.4 0.4 0.4 1"/>
      </material>
    </visual>
  </link>
  <joint name="connection_joint" type="fixed">
    <parent link="ft_sensor_frame_right"/>
    <origin rpy="0 0 0" xyz="0 0 0.0125"/>
    <child link="connection_link"/>
  </joint>
</robot>

