<?xml version="1.0" encoding="utf-8"?>
<!-- =================================================================================== -->
<!-- |    This document was autogenerated by xacro from use_case_setup_iiwa.urdf.xacro | -->
<!-- |    EDITING THIS FILE BY HAND IS NOT RECOMMENDED                                 | -->
<!-- =================================================================================== -->
<robot name="iiwa_setup">
  <material name="Black">
    <color rgba="0.0 0.0 0.0 1.0"/>
  </material>
  <material name="Blue">
    <color rgba="0.0 0.0 0.8 1.0"/>
  </material>
  <material name="Green">
    <color rgba="0.0 0.8 0.0 1.0"/>
  </material>
  <material name="Yellow">
    <color rgba="0.6 0.6 0 1.0"/>
  </material>
  <material name="Orange">
    <color rgba="1.0 0.423529411765 0.0392156862745 1.0"/>
  </material>
  <material name="Brown">
    <color rgba="0.870588235294 0.811764705882 0.764705882353 1.0"/>
  </material>
  <material name="Brown_table">
    <color rgba="0.545098039216 0.270588235294 0.0745098039216 1"/>
  </material>
  <material name="Red">
    <color rgba="0.8 0.0 0.0 1.0"/>
  </material>
  <material name="White">
    <color rgba="1.0 1.0 1.0 1.0"/>
  </material>
  <material name="Soft Grey">
    <color rgba=".4 .4 .4 1"/>
  </material>
  <material name="Dark Grey">
    <color rgba=".2 .2 .2 1"/>
  </material>
  <material name="Bright Grey">
    <color rgba=".6 .6 .6 1"/>
  </material>
  <material name="Beige">
    <color rgba="0.870588235294 0.721568627451 0.529411764706 1"/>
  </material>
  <material name="Gold">
    <color rgba="0.517647058824 0.411764705882 0.192156862745 1"/>
  </material>
  <gazebo>
    <plugin filename="libgazebo_ros_control.so" name="gazebo_ros_controller">
      <robotNamespace>/lbr_iiwa</robotNamespace>
    </plugin>
  </gazebo>
  <!-- Fix robot to world-->
  <link name="world"/>
  <!--joint between {parent} and link_0-->
  <joint name="world_joint" type="fixed">
    <origin rpy="0 0 0" xyz="0 0 0.0"/>
    <parent link="world"/>
    <child link="lbr_iiwa_link_0"/>
  </joint>
  <link name="lbr_iiwa_link_0">
    <inertial>
      <origin rpy="0 0 0" xyz="-0.1 0 0.07"/>
      <mass value="5"/>
      <inertia ixx="0.05" ixy="0" ixz="0" iyy="0.06" iyz="0" izz="0.03"/>
    </inertial>
    <visual>
      <origin rpy="0 0 0" xyz="0 0 0"/>
      <geometry>
        <mesh filename="package://lbr_iiwa_description/meshes/link_0.stl"/>
      </geometry>
      <material name="Grey"/>
    </visual>
    <collision>
      <origin rpy="0 0 0" xyz="0 0 0"/>
      <geometry>
        <mesh filename="package://lbr_iiwa_description/meshes/coarse/link_0.stl"/>
      </geometry>
      <material name="Grey"/>
    </collision>
    <self_collision_checking>
      <origin rpy="0 0 0" xyz="0 0 0"/>
      <geometry>
        <capsule length="0.25" radius="0.15"/>
      </geometry>
    </self_collision_checking>
  </link>
  <!-- joint between link_0 and link_1 -->
  <joint name="lbr_iiwa_joint_1" type="revolute">
    <parent link="lbr_iiwa_link_0"/>
    <child link="lbr_iiwa_link_1"/>
    <origin rpy="0 0 0" xyz="0 0 0.1575"/>
    <axis xyz="0 0 1"/>
    <limit effort="300" lower="-2.96705972839" upper="2.96705972839" velocity="10"/>
    <!--   <safety_controller soft_lower_limit="${-168 * M_PI / 180}"
           soft_upper_limit="${168 * M_PI / 180}"
           k_position="${safety_controller_k_pos}"
           k_velocity="${safety_controller_k_vel}"/> -->
    <dynamics damping="0.5"/>
  </joint>
  <link name="lbr_iiwa_link_1">
    <inertial>
      <origin rpy="0 0 0" xyz="0 -0.03 0.12"/>
      <mass value="4"/>
      <inertia ixx="0.1" ixy="0" ixz="0" iyy="0.09" iyz="0" izz="0.02"/>
    </inertial>
    <visual>
      <origin rpy="0 0 0" xyz="0 0 0"/>
      <geometry>
        <mesh filename="package://lbr_iiwa_description/meshes/link_1.stl"/>
      </geometry>
      <material name="Orange"/>
    </visual>
    <collision>
      <origin rpy="0 0 0" xyz="0 0 0"/>
      <geometry>
        <mesh filename="package://lbr_iiwa_description/meshes/coarse/link_1.stl"/>
      </geometry>
      <material name="Orange"/>
    </collision>
  </link>
  <!-- joint between link_1 and link_2 -->
  <joint name="lbr_iiwa_joint_2" type="revolute">
    <parent link="lbr_iiwa_link_1"/>
    <child link="lbr_iiwa_link_2"/>
    <origin rpy="1.57079632679   0 3.14159265359" xyz="0 0 0.2025"/>
    <axis xyz="0 0 1"/>
    <limit effort="300" lower="-2.09439510239" upper="2.09439510239" velocity="10"/>
    <!-- <safety_controller soft_lower_limit="${-118 * PI / 180}"
           soft_upper_limit="${118 * PI / 180}"
           k_position="${safety_controller_k_pos}"
           k_velocity="${safety_controller_k_vel}"/> -->
    <dynamics damping="0.5"/>
  </joint>
  <link name="lbr_iiwa_link_2">
    <inertial>
      <origin rpy="0 0 0" xyz="0.0003 0.059 0.042"/>
      <mass value="4"/>
      <inertia ixx="0.05" ixy="0" ixz="0" iyy="0.018" iyz="0" izz="0.044"/>
    </inertial>
    <visual>
      <origin rpy="0 0 0" xyz="0 0 0"/>
      <geometry>
        <mesh filename="package://lbr_iiwa_description/meshes/link_2.stl"/>
      </geometry>
      <material name="Orange"/>
    </visual>
    <collision>
      <origin rpy="0 0 0" xyz="0 0 0"/>
      <geometry>
        <mesh filename="package://lbr_iiwa_description/meshes/coarse/link_2.stl"/>
      </geometry>
      <material name="Orange"/>
    </collision>
  </link>
  <!-- joint between link_2 and link_3 -->
  <joint name="lbr_iiwa_joint_3" type="revolute">
    <parent link="lbr_iiwa_link_2"/>
    <child link="lbr_iiwa_link_3"/>
    <origin rpy="1.57079632679 0 3.14159265359" xyz="0 0.2045 0"/>
    <axis xyz="0 0 1"/>
    <limit effort="300" lower="-2.96705972839" upper="2.96705972839" velocity="10"/>
    <!-- <safety_controller soft_lower_limit="${-118 * PI / 180}"
           soft_upper_limit="${118 * PI / 180}"
           k_position="${safety_controller_k_pos}"
           k_velocity="${safety_controller_k_vel}"/> -->
    <dynamics damping="0.5"/>
  </joint>
  <link name="lbr_iiwa_link_3">
    <inertial>
      <origin rpy="0 0 0" xyz="0 0.03 0.13"/>
      <mass value="3"/>
      <inertia ixx="0.08" ixy="0" ixz="0" iyy="0.075" iyz="0" izz="0.01"/>
    </inertial>
    <visual>
      <origin rpy="0 0 0" xyz="0 0 0"/>
      <geometry>
        <mesh filename="package://lbr_iiwa_description/meshes/link_3.stl"/>
      </geometry>
      <material name="Orange"/>
    </visual>
    <collision>
      <origin rpy="0 0 0" xyz="0 0 0"/>
      <geometry>
        <mesh filename="package://lbr_iiwa_description/meshes/coarse/link_3.stl"/>
      </geometry>
      <material name="Orange"/>
    </collision>
  </link>
  <!-- joint between link_3 and link_4 -->
  <joint name="lbr_iiwa_joint_4" type="revolute">
    <parent link="lbr_iiwa_link_3"/>
    <child link="lbr_iiwa_link_4"/>
    <origin rpy="1.57079632679 0 0" xyz="0 0 0.2155"/>
    <axis xyz="0 0 1"/>
    <limit effort="300" lower="-2.09439510239" upper="2.09439510239" velocity="10"/>
    <!-- <safety_controller soft_lower_limit="${-118 * PI / 180}"
           soft_upper_limit="${118 * PI / 180}"
           k_position="${safety_controller_k_pos}"
           k_velocity="${safety_controller_k_vel}"/> -->
    <dynamics damping="0.5"/>
  </joint>
  <link name="lbr_iiwa_link_4">
    <inertial>
      <origin rpy="0 0 0" xyz="0 0.067 0.034"/>
      <mass value="2.7"/>
      <inertia ixx="0.03" ixy="0" ixz="0" iyy="0.01" iyz="0" izz="0.029"/>
    </inertial>
    <visual>
      <origin rpy="0 0 0" xyz="0 0 0"/>
      <geometry>
        <mesh filename="package://lbr_iiwa_description/meshes/link_4.stl"/>
      </geometry>
      <material name="Orange"/>
    </visual>
    <collision>
      <origin rpy="0 0 0" xyz="0 0 0"/>
      <geometry>
        <mesh filename="package://lbr_iiwa_description/meshes/coarse/link_4.stl"/>
      </geometry>
      <material name="Orange"/>
    </collision>
  </link>
  <!-- joint between link_4 and link_5 -->
  <joint name="lbr_iiwa_joint_5" type="revolute">
    <parent link="lbr_iiwa_link_4"/>
    <child link="lbr_iiwa_link_5"/>
    <origin rpy="-1.57079632679 3.14159265359 0" xyz="0 0.1845 0"/>
    <axis xyz="0 0 1"/>
    <limit effort="300" lower="-2.96705972839" upper="2.96705972839" velocity="10"/>
    <!-- <safety_controller soft_lower_limit="${-118 * PI / 180}"
           soft_upper_limit="${118 * PI / 180}"
           k_position="${safety_controller_k_pos}"
           k_velocity="${safety_controller_k_vel}"/> -->
    <dynamics damping="0.5"/>
  </joint>
  <link name="lbr_iiwa_link_5">
    <inertial>
      <origin rpy="0 0 0" xyz="0.0001 0.021 0.076"/>
      <mass value="1.7"/>
      <inertia ixx="0.02" ixy="0" ixz="0" iyy="0.018" iyz="0" izz="0.005"/>
    </inertial>
    <visual>
      <origin rpy="0 0 0" xyz="0 0 0"/>
      <geometry>
        <mesh filename="package://lbr_iiwa_description/meshes/link_5.stl"/>
      </geometry>
      <material name="Orange"/>
    </visual>
    <collision>
      <origin rpy="0 0 0" xyz="0 0 0"/>
      <geometry>
        <mesh filename="package://lbr_iiwa_description/meshes/coarse/link_5.stl"/>
      </geometry>
      <material name="Orange"/>
    </collision>
  </link>
  <!-- joint between link_5 and link_6 -->
  <joint name="lbr_iiwa_joint_6" type="revolute">
    <parent link="lbr_iiwa_link_5"/>
    <child link="lbr_iiwa_link_6"/>
    <origin rpy="1.57079632679 0 0" xyz="0 0 0.2155"/>
    <axis xyz="0 0 1"/>
    <limit effort="300" lower="-2.09439510239" upper="2.09439510239" velocity="10"/>
    <!-- <safety_controller soft_lower_limit="${-118 * PI / 180}"
           soft_upper_limit="${118 * PI / 180}"
           k_position="${safety_controller_k_pos}"
           k_velocity="${safety_controller_k_vel}"/> -->
    <dynamics damping="0.5"/>
  </joint>
  <link name="lbr_iiwa_link_6">
    <inertial>
      <origin rpy="0 0 0" xyz="0 0.0006 0.0004"/>
      <mass value="1.8"/>
      <inertia ixx="0.005" ixy="0" ixz="0" iyy="0.0036" iyz="0" izz="0.0047"/>
    </inertial>
    <visual>
      <origin rpy="0 0 0" xyz="0 0 0"/>
      <geometry>
        <mesh filename="package://lbr_iiwa_description/meshes/link_6.stl"/>
      </geometry>
      <material name="Orange"/>
    </visual>
    <collision>
      <origin rpy="0 0 0" xyz="0 0 0"/>
      <geometry>
        <mesh filename="package://lbr_iiwa_description/meshes/coarse/link_6.stl"/>
      </geometry>
      <material name="Orange"/>
    </collision>
  </link>
  <!-- joint between link_6 and link_7 -->
  <joint name="lbr_iiwa_joint_7" type="revolute">
    <parent link="lbr_iiwa_link_6"/>
    <child link="lbr_iiwa_link_7"/>
    <origin rpy="-1.57079632679 3.14159265359 0" xyz="0 0.081 0"/>
    <axis xyz="0 0 1"/>
    <limit effort="300" lower="-3.05432619099" upper="3.05432619099" velocity="10"/>
    <!-- <safety_controller soft_lower_limit="${-118 * PI / 180}"
           soft_upper_limit="${118 * PI / 180}"
           k_position="${safety_controller_k_pos}"
           k_velocity="${safety_controller_k_vel}"/> -->
    <dynamics damping="0.5"/>
  </joint>
  <link name="lbr_iiwa_link_7">
    <inertial>
      <origin rpy="0 0 0" xyz="0 0 0.02"/>
      <mass value="0.3"/>
      <inertia ixx="0.001" ixy="0" ixz="0" iyy="0.001" iyz="0" izz="0.001"/>
    </inertial>
    <visual>
      <origin rpy="0 0 0" xyz="0 0 0"/>
      <geometry>
        <mesh filename="package://lbr_iiwa_description/meshes/link_7_adaptor.stl" scale="0.001 0.001 0.001"/>
      </geometry>
      <material name="Gold"/>
    </visual>
    <collision>
      <origin rpy="0 0 0" xyz="0 0 0"/>
      <geometry>
        <mesh filename="package://lbr_iiwa_description/meshes/coarse/link_7_adaptor.stl"/>
      </geometry>
      <material name="Grey"/>
    </collision>
  </link>
  <!-- Gripper -->
  <!-- Left -->
  <link name="left_gripper">
    <visual>
      <geometry>
        <mesh filename="package://lbr_iiwa_description/meshes/finger.stl" scale="0.001 0.001 0.001"/>
      </geometry>
      <origin rpy="0 0 0" xyz="0 0 0"/>
      <material name="Soft Grey"/>
    </visual>
  </link>
  <joint name="left_finger" type="prismatic">
    <axis xyz="0 1 0"/>
    <parent link="lbr_iiwa_link_7"/>
    <child link="left_gripper"/>
    <origin rpy="0 0 0" xyz="0 0 0.2026"/>
    <limit effort="1000.0" lower="0" upper=".03" velocity="0.5"/>
  </joint>
  <!-- Right -->
  <link name="right_gripper">
    <visual>
      <geometry>
        <mesh filename="package://lbr_iiwa_description/meshes/finger.stl" scale="0.001 0.001 0.001"/>
      </geometry>
      <origin rpy="0 0 3.14159265359" xyz="0 0 0"/>
      <material name="Soft Grey"/>
    </visual>
  </link>
  <joint name="right_finger" type="prismatic">
    <axis xyz="0 1 0"/>
    <parent link="lbr_iiwa_link_7"/>
    <child link="right_gripper"/>
    <origin rpy="0 0 0" xyz="0 0 0.2026"/>
    <limit effort="1000.0" lower="-.03" upper="0" velocity="0.5"/>
  </joint>
  <!-- Link0 -->
  <gazebo reference="lbr_iiwa_link_0">
    <material>Gazebo/Grey</material>
    <mu1>0.2</mu1>
    <mu2>0.2</mu2>
  </gazebo>
  <!-- Link1 -->
  <gazebo reference="lbr_iiwa_link_1">
    <material>Gazebo/Orange</material>
    <mu1>0.2</mu1>
    <mu2>0.2</mu2>
  </gazebo>
  <!-- Link2 -->
  <gazebo reference="lbr_iiwa_link_2">
    <material>Gazebo/Orange</material>
    <mu1>0.2</mu1>
    <mu2>0.2</mu2>
  </gazebo>
  <!-- Link3 -->
  <gazebo reference="lbr_iiwa_link_3">
    <material>Gazebo/Orange</material>
    <mu1>0.2</mu1>
    <mu2>0.2</mu2>
  </gazebo>
  <!-- Link4 -->
  <gazebo reference="lbr_iiwa_link_4">
    <material>Gazebo/Orange</material>
    <mu1>0.2</mu1>
    <mu2>0.2</mu2>
  </gazebo>
  <!-- Link5 -->
  <gazebo reference="lbr_iiwa_link_5">
    <material>Gazebo/Orange</material>
    <mu1>0.2</mu1>
    <mu2>0.2</mu2>
  </gazebo>
  <!-- Link6 -->
  <gazebo reference="lbr_iiwa_link_6">
    <material>Gazebo/Orange</material>
    <mu1>0.2</mu1>
    <mu2>0.2</mu2>
  </gazebo>
  <!-- Link7 -->
  <gazebo reference="lbr_iiwa_link_7">
    <material>Gazebo/Grey</material>
    <mu1>0.2</mu1>
    <mu2>0.2</mu2>
  </gazebo>
  <transmission name="lbr_iiwa_tran_1">
    <type>transmission_interface/SimpleTransmission</type>
    <joint name="lbr_iiwa_joint_1">
      <hardwareInterface></hardwareInterface>
    </joint>
    <actuator name="lbr_iiwa_motor_1">
      <hardwareInterface></hardwareInterface>
      <mechanicalReduction>1</mechanicalReduction>
    </actuator>
  </transmission>
  <transmission name="lbr_iiwa_tran_2">
    <type>transmission_interface/SimpleTransmission</type>
    <joint name="lbr_iiwa_joint_2">
      <hardwareInterface></hardwareInterface>
    </joint>
    <actuator name="lbr_iiwa_motor_2">
      <hardwareInterface></hardwareInterface>
      <mechanicalReduction>1</mechanicalReduction>
    </actuator>
  </transmission>
  <transmission name="lbr_iiwa_tran_3">
    <type>transmission_interface/SimpleTransmission</type>
    <joint name="lbr_iiwa_joint_3">
      <hardwareInterface></hardwareInterface>
    </joint>
    <actuator name="lbr_iiwa_motor_3">
      <hardwareInterface></hardwareInterface>
      <mechanicalReduction>1</mechanicalReduction>
    </actuator>
  </transmission>
  <transmission name="lbr_iiwa_tran_4">
    <type>transmission_interface/SimpleTransmission</type>
    <joint name="lbr_iiwa_joint_4">
      <hardwareInterface></hardwareInterface>
    </joint>
    <actuator name="lbr_iiwa_motor_4">
      <hardwareInterface></hardwareInterface>
      <mechanicalReduction>1</mechanicalReduction>
    </actuator>
  </transmission>
  <transmission name="lbr_iiwa_tran_5">
    <type>transmission_interface/SimpleTransmission</type>
    <joint name="lbr_iiwa_joint_5">
      <hardwareInterface></hardwareInterface>
    </joint>
    <actuator name="lbr_iiwa_motor_5">
      <hardwareInterface></hardwareInterface>
      <mechanicalReduction>1</mechanicalReduction>
    </actuator>
  </transmission>
  <transmission name="lbr_iiwa_tran_6">
    <type>transmission_interface/SimpleTransmission</type>
    <joint name="lbr_iiwa_joint_6">
      <hardwareInterface></hardwareInterface>
    </joint>
    <actuator name="lbr_iiwa_motor_6">
      <hardwareInterface></hardwareInterface>
      <mechanicalReduction>1</mechanicalReduction>
    </actuator>
  </transmission>
  <transmission name="lbr_iiwa_tran_7">
    <type>transmission_interface/SimpleTransmission</type>
    <joint name="lbr_iiwa_joint_7">
      <hardwareInterface></hardwareInterface>
    </joint>
    <actuator name="lbr_iiwa_motor_7">
      <hardwareInterface></hardwareInterface>
      <mechanicalReduction>1</mechanicalReduction>
    </actuator>
  </transmission>
  <!-- combined scene -->
  <link name="tool_frame"/>
  <joint name="tool_frame_joint" type="fixed">
    <origin rpy="0.0 0.0 0.0" xyz="0 0 0"/>
    <parent link="lbr_iiwa_link_7"/>
    <child link="tool_frame"/>
  </joint>
</robot>

